2024-02-24 21:14:45,356 - root - INFO - Bot is now running
2024-02-24 21:14:47,208 - root - INFO - Sending start text
2024-02-24 21:14:49,583 - root - INFO - Sending doc to user
2024-02-24 21:14:51,514 - root - INFO - Sending HowTo text
2024-02-24 21:17:40,835 - root - INFO - Success! send response to user
2024-02-24 21:17:41,031 - root - INFO - Waiting choice from user
2024-02-24 21:17:52,810 - root - INFO - User waiting
2024-02-24 21:18:48,829 - root - INFO - Success! send response to user
2024-02-24 21:18:48,954 - root - INFO - Waiting choice from user
2024-02-24 21:19:50,911 - root - INFO - Success! send response to user
2024-02-24 21:19:51,148 - root - INFO - Waiting choice from user
2024-02-24 21:20:16,939 - root - INFO - Success! send response to user
2024-02-24 21:20:17,042 - root - INFO - Waiting choice from user
2024-02-24 21:21:16,673 - TeleBot - ERROR - Infinity polling exception: HTTPConnectionPool(host='localhost', port=1234): Max retries exceeded with url: /v1/chat/completions (Caused by NewConnectionError('<urllib3.connection.HTTPConnection object at 0x000001D5223295B0>: Failed to establish a new connection: [WinError 10061] Подключение не установлено, т.к. конечный компьютер отверг запрос на подключение'))
2024-02-24 21:21:16,676 - TeleBot - ERROR - Exception traceback:
Traceback (most recent call last):
  File "E:\pythonProject\my_first_python_project\tggptbot\venv\lib\site-packages\urllib3\connection.py", line 174, in _new_conn
    conn = connection.create_connection(
  File "E:\pythonProject\my_first_python_project\tggptbot\venv\lib\site-packages\urllib3\util\connection.py", line 95, in create_connection
    raise err
  File "E:\pythonProject\my_first_python_project\tggptbot\venv\lib\site-packages\urllib3\util\connection.py", line 85, in create_connection
    sock.connect(sa)
ConnectionRefusedError: [WinError 10061] Подключение не установлено, т.к. конечный компьютер отверг запрос на подключение

During handling of the above exception, another exception occurred:

Traceback (most recent call last):
  File "E:\pythonProject\my_first_python_project\tggptbot\venv\lib\site-packages\urllib3\connectionpool.py", line 715, in urlopen
    httplib_response = self._make_request(
  File "E:\pythonProject\my_first_python_project\tggptbot\venv\lib\site-packages\urllib3\connectionpool.py", line 416, in _make_request
    conn.request(method, url, **httplib_request_kw)
  File "E:\pythonProject\my_first_python_project\tggptbot\venv\lib\site-packages\urllib3\connection.py", line 244, in request
    super(HTTPConnection, self).request(method, url, body=body, headers=headers)
  File "C:\Users\Admin\AppData\Local\Programs\Python\Python39\lib\http\client.py", line 1285, in request
    self._send_request(method, url, body, headers, encode_chunked)
  File "C:\Users\Admin\AppData\Local\Programs\Python\Python39\lib\http\client.py", line 1331, in _send_request
    self.endheaders(body, encode_chunked=encode_chunked)
  File "C:\Users\Admin\AppData\Local\Programs\Python\Python39\lib\http\client.py", line 1280, in endheaders
    self._send_output(message_body, encode_chunked=encode_chunked)
  File "C:\Users\Admin\AppData\Local\Programs\Python\Python39\lib\http\client.py", line 1040, in _send_output
    self.send(msg)
  File "C:\Users\Admin\AppData\Local\Programs\Python\Python39\lib\http\client.py", line 980, in send
    self.connect()
  File "E:\pythonProject\my_first_python_project\tggptbot\venv\lib\site-packages\urllib3\connection.py", line 205, in connect
    conn = self._new_conn()
  File "E:\pythonProject\my_first_python_project\tggptbot\venv\lib\site-packages\urllib3\connection.py", line 186, in _new_conn
    raise NewConnectionError(
urllib3.exceptions.NewConnectionError: <urllib3.connection.HTTPConnection object at 0x000001D5223295B0>: Failed to establish a new connection: [WinError 10061] Подключение не установлено, т.к. конечный компьютер отверг запрос на подключение

During handling of the above exception, another exception occurred:

Traceback (most recent call last):
  File "E:\pythonProject\my_first_python_project\tggptbot\venv\lib\site-packages\requests\adapters.py", line 486, in send
    resp = conn.urlopen(
  File "E:\pythonProject\my_first_python_project\tggptbot\venv\lib\site-packages\urllib3\connectionpool.py", line 799, in urlopen
    retries = retries.increment(
  File "E:\pythonProject\my_first_python_project\tggptbot\venv\lib\site-packages\urllib3\util\retry.py", line 592, in increment
    raise MaxRetryError(_pool, url, error or ResponseError(cause))
urllib3.exceptions.MaxRetryError: HTTPConnectionPool(host='localhost', port=1234): Max retries exceeded with url: /v1/chat/completions (Caused by NewConnectionError('<urllib3.connection.HTTPConnection object at 0x000001D5223295B0>: Failed to establish a new connection: [WinError 10061] Подключение не установлено, т.к. конечный компьютер отверг запрос на подключение'))

During handling of the above exception, another exception occurred:

Traceback (most recent call last):
  File "E:\pythonProject\my_first_python_project\tggptbot\venv\lib\site-packages\telebot\__init__.py", line 1016, in infinity_polling
    self.polling(non_stop=True, timeout=timeout, long_polling_timeout=long_polling_timeout,
  File "E:\pythonProject\my_first_python_project\tggptbot\venv\lib\site-packages\telebot\__init__.py", line 1104, in polling
    self.__threaded_polling(non_stop=non_stop, interval=interval, timeout=timeout, long_polling_timeout=long_polling_timeout,
  File "E:\pythonProject\my_first_python_project\tggptbot\venv\lib\site-packages\telebot\__init__.py", line 1179, in __threaded_polling
    raise e
  File "E:\pythonProject\my_first_python_project\tggptbot\venv\lib\site-packages\telebot\__init__.py", line 1141, in __threaded_polling
    self.worker_pool.raise_exceptions()
  File "E:\pythonProject\my_first_python_project\tggptbot\venv\lib\site-packages\telebot\util.py", line 149, in raise_exceptions
    raise self.exception_info
  File "E:\pythonProject\my_first_python_project\tggptbot\venv\lib\site-packages\telebot\util.py", line 92, in run
    task(*args, **kwargs)
  File "E:\pythonProject\my_first_python_project\tggptbot\bot.py", line 88, in get_promt
    resp = gpt.send_request(json)
  File "E:\pythonProject\my_first_python_project\tggptbot\gpt.py", line 66, in send_request
    resp = requests.post(url=self.URL, headers=self.HEADERS, json=json)
  File "E:\pythonProject\my_first_python_project\tggptbot\venv\lib\site-packages\requests\api.py", line 115, in post
    return request("post", url, data=data, json=json, **kwargs)
  File "E:\pythonProject\my_first_python_project\tggptbot\venv\lib\site-packages\requests\api.py", line 59, in request
    return session.request(method=method, url=url, **kwargs)
  File "E:\pythonProject\my_first_python_project\tggptbot\venv\lib\site-packages\requests\sessions.py", line 589, in request
    resp = self.send(prep, **send_kwargs)
  File "E:\pythonProject\my_first_python_project\tggptbot\venv\lib\site-packages\requests\sessions.py", line 703, in send
    r = adapter.send(request, **kwargs)
  File "E:\pythonProject\my_first_python_project\tggptbot\venv\lib\site-packages\requests\adapters.py", line 519, in send
    raise ConnectionError(e, request=request)
requests.exceptions.ConnectionError: HTTPConnectionPool(host='localhost', port=1234): Max retries exceeded with url: /v1/chat/completions (Caused by NewConnectionError('<urllib3.connection.HTTPConnection object at 0x000001D5223295B0>: Failed to establish a new connection: [WinError 10061] Подключение не установлено, т.к. конечный компьютер отверг запрос на подключение'))

2024-02-24 21:21:28,681 - TeleBot - ERROR - Infinity polling: polling exited
2024-02-24 21:21:28,681 - TeleBot - ERROR - Break infinity polling
